<?xml version="1.0" ?>
<sdf version="1.8">
    <world name="robot_wheeled">

        <model name='robot' canonical_link='base_link'>
            <pose relative_to='world'>0 0 0 0 0 0</pose>            <!--the pose is relative to the world by default-->
            <!--chassis-->
            <link name='base_link'>
                <pose relative_to='__model__'>0.5 0 0.4 0 0 0</pose>
                <inertial>                    <!--inertial properties of the link mass, inertia matix-->
                    <mass>1.14395</mass>
                    <inertia>
                        <ixx>0.095329</ixx>
                        <ixy>0</ixy>
                        <ixz>0</ixz>
                        <iyy>0.381317</iyy>
                        <iyz>0</iyz>
                        <izz>0.476646</izz>
                    </inertia>
                </inertial>
                <visual name='visual'>
                    <geometry>
                        <box>
                            <size>2.0 1.0 0.5</size>
                        </box>
                    </geometry>
                </visual>
            </link>

            <!--Left wheel-->
            <link name='left_wheel'>
                <pose relative_to="base_link">-0.5 0.6 0 -1.5707 0 0</pose>                <!--angles are in radian-->
                <visual name='visual'>
                    <geometry>
                        <cylinder>
                            <radius>0.4</radius>
                            <length>0.2</length>
                        </cylinder>
                    </geometry>
                </visual>
                <collision name='collision'>
                    <geometry>
                        <cylinder>
                            <radius>0.4</radius>
                            <length>0.2</length>
                        </cylinder>
                    </geometry>
                </collision>
            </link>

            <!--The same as left wheel but with different position-->
            <link name='right_wheel'>
                <pose relative_to="base_link">-0.5 -0.6 0 -1.5707 0 0</pose>                <!--angles are in radian-->
                <visual name='visual'>
                    <geometry>
                        <cylinder>
                            <radius>0.4</radius>
                            <length>0.2</length>
                        </cylinder>
                    </geometry>
                </visual>
            </link>

            <!--arbitrary frame-->
            <frame name="caster_frame" attached_to='base_link'>
                <pose>0.8 0 -0.2 0 0 0</pose>
            </frame>

            <!--caster wheel-->
            <link name='caster'>
                <pose relative_to='caster_frame'/>
                <inertial>
                    <mass>1</mass>
                </inertial>
                <visual name='visual'>
                    <geometry>
                        <sphere>
                            <radius>0.2</radius>
                        </sphere>
                    </geometry>
                </visual>
            </link>

            <!--left wheel joint-->
            <joint name='left_wheel_joint' type='revolute'>
                <pose relative_to='left_wheel'/>
                <parent>base_link</parent>
                <child>left_wheel</child>
                <axis>
                    <xyz expressed_in='__model__'>0 1 0</xyz>                    <!--can be descired to any frame or even arbitrary frames-->
                    <limit>
                        <lower>-1.79769e+308</lower>                        <!--negative infinity-->
                        <upper>1.79769e+308</upper>                        <!--positive infinity-->
                    </limit>
                </axis>
            </joint>

            <!--right wheel joint-->
            <joint name='right_wheel_joint' type='revolute'>
                <pose relative_to='right_wheel'/>
                <parent>base_link</parent>
                <child>right_wheel</child>
                <axis>
                    <xyz expressed_in='__model__'>0 1 0</xyz>
                    <limit>
                        <lower>-1.79769e+308</lower>                        <!--negative infinity-->
                        <upper>1.79769e+308</upper>                        <!--positive infinity-->
                    </limit>
                </axis>
            </joint>

            <!--caster wheel joint-->            <!--pose defult value is the child-->
            <joint name='caster_wheel' type='ball'>
                <parent>base_link</parent>
                <child>caster</child>
            </joint>
        </model>
    </world>
</sdf>